<mujoco model="reacher">
	<compiler angle="radian" inertiafromgeom="true"/>
	<default>
		<joint armature="1" damping="1" limited="true"/>
		<geom contype="0" friction="1 0.1 0.1" rgba="0.7 0.7 0 1"/>
	</default>

	<option gravity="0 0 -9.81" integrator="RK4" timestep="0.01"/>
	<worldbody>
		<!-- Arena -->
		<geom conaffinity="0" contype="0" name="ground" pos="0 0 0" rgba="0.9 0.9 0.9 1" size="1 1 10" type="plane"/>
		<geom conaffinity="0" fromto="-.6 -.6 .01 .6 -.6 .01" name="sideS" rgba="0.9 0.4 0.6 1" size=".01" type="capsule"/>
		<geom conaffinity="0" fromto=" .6 -.6 .01 .6  .6 .01" name="sideE" rgba="0.9 0.4 0.6 1" size=".01" type="capsule"/>
		<geom conaffinity="0" fromto="-.6  .6 .01 .6  .6 .01" name="sideN" rgba="0.9 0.4 0.6 1" size=".01" type="capsule"/>
		<geom conaffinity="0" fromto="-.6 -.6 .01 -.6 .6 .01" name="sideW" rgba="0.9 0.4 0.6 1" size=".01" type="capsule"/>
		
		<!-- Arm -->
		<geom conaffinity="0" contype="0" fromto="0 0 0 0 0 0.02" name="root" rgba="0.9 0.4 0.6 1" size=".011" type="cylinder"/>

		<!-- pos is body start position -->
		<body name="body0" pos="0 0 .01">
			<joint axis="0 0 1" limited="true" name="joint0" pos="0 0 0" range="-3.14 3.14" type="hinge"/>
			<!-- fromto is body start position to end position => geom size -->
			<geom fromto="0 0 0 0 0 0.16" name="link0" rgba="0.2 0.4 0.6 1" size=".01" type="capsule"/>

			<body name="body1" pos="0 0 .16">
				<joint axis="0 1 0" limited="true" name="joint1" pos="0 0 0" range="-1.57 1.57" type="hinge"/>
				<geom fromto="0 0 0 0 0 0.29" name="link1" rgba="0.4 0.4 0.6 1" size=".01" type="capsule"/>

				<body name="body2" pos="0 0 0.29">
				<joint axis="0 1 0" limited="true" name="joint2" pos="0 0 0" range="-1.57 1.57" type="hinge"/>
				<geom fromto="0 0 0 0 0 0.26" name="link2" rgba="0.6 0.4 0.6 1" size=".01" type="capsule"/>

					<body name="body3" pos="0 0 0.13">
					<joint axis="0 0 1" limited="true" name="joint3" pos="0 0 0" range="-3.14 3.14" type="hinge"/>
					<!-- <geom fromto="0 0 0 0 0 0.13" name="link3" rgba="0.6 0.4 0.4 1" size=".01" type="capsule"/> -->

						<body name="body4" pos="0 0 0.13">
						<joint axis="0 1 0" limited="true" name="joint4" pos="0 0 0" range="-1.57 1.57" type="hinge"/>
						<geom fromto="0 0 0 0 0 0.134" name="link4" rgba="0.6 0.4 0.2 1" size=".01" type="capsule"/>

							<body name="body5" pos="0 0 0.1">
							<joint axis="0 0 1" limited="true" name="joint5" pos="0 0 0" range="-3.14 3.14" type="hinge"/>
							<!-- <geom fromto="0 0 0 0 0 0.04" name="link5" rgba="0.6 0.2 0.2 1" size=".01" type="capsule"/> -->

								<!-- End-Effort -->
								<body name="fingertip" pos="0 0 0.034">
									<geom contype="0" name="fingertip" pos="0 0 0" rgba="0.0 0.8 0.6 1" size=".01" type="sphere"/>
								</body>
								
							</body>
						</body>
					</body>
				</body>
			</body>
		</body>

		<!-- Target -->
		<body name="target" pos="0 0 .01">
			<joint armature="0" axis="1 0 0" damping="0" limited="true" name="target_x" pos="0 0 0" range="-.5 .5" stiffness="0" type="slide"/>
			<joint armature="0" axis="0 1 0" damping="0" limited="true" name="target_y" pos="0 0 0" range="-.5 .5" stiffness="0" type="slide"/>
			<joint armature="0" axis="0 0 1" damping="0" limited="true" name="target_z" pos="0 0 0" range="0.0 .1" stiffness="0" type="slide"/>
			<geom conaffinity="0" contype="0" name="target" pos="0 0 0" rgba="0.9 0.2 0.2 1" size=".009" type="sphere"/>
		</body>
	</worldbody>

	<actuator>
		<motor ctrllimited="true" ctrlrange="-1.0 1.0" gear="600.0" joint="joint0"/>
		<motor ctrllimited="true" ctrlrange="-1.0 1.0" gear="600.0" joint="joint1"/>
		<motor ctrllimited="true" ctrlrange="-1.0 1.0" gear="400.0" joint="joint2"/>
		<motor ctrllimited="true" ctrlrange="-1.0 1.0" gear="400.0" joint="joint3"/>
		<motor ctrllimited="true" ctrlrange="-1.0 1.0" gear="200.0" joint="joint4"/>
		<motor ctrllimited="true" ctrlrange="-1.0 1.0" gear="200.0" joint="joint5"/>
	</actuator>
</mujoco>
